Workbook

Sheet Invoice
A2: Module Code | B2: Quản lí hóa đơn | M2: Pass
A3: Test requirement | B3: Hệ thống cho phép người quản trị xem hóa đơn, hủy đơn hàng và chỉnh sửa trạng thái đơn hàng | M3: Fail
A4: Tester | B4: Vũ Hồng
A5: Pass | B5: Fail | C5: Untested | D5: N/A | E5: Number of Test cases | M5: Untesed
A6: =COUNTIF(I9:I982,"Pass") -> 12 | B6: =COUNTIF(I9:I982,"Fail") -> 1 | C6: =E6-D6-A6-B6 -> 1 | D6: =COUNTIF(H$9:I$982,"N/A") -> 1 | E6: =COUNTA(A9:A986) -> 15 | M6: N/A
A8: ID | B8: Group Name | C8: Sub Group Name | D8: Test Case Description | E8: Precondition | F8: Test Case Procedure | G8: Test data | H8: Expected Output | I8: Result | J8: Test date | K8: Note
A9: =$B$2&"-"&ROW()-8 -> Quản lí hóa đơn-1 | B9: Access right | D9: Kiểm tra quyền truy cập với user là Admin | E9: Đang ở trang admin | F9: 1. Click Hóa đơn | G9: Tên đăng nhập: Admin Mật khẩu: admin | H9: Hệ thống sẽ hiển thị tất cả các hóa đơn | I9: Pass
A10: =$B$2&"-"&ROW()-8 -> Quản lí hóa đơn-2 | D10: Kiểm tra quyền truy cập với user là Khách hàng | E10: User đăng nhập với tài khoản Khách hàng | F10: 1. Mở trang chủ 2. Click vào giỏ hàng | G10: Tên đăng nhập: test_1 Mật khẩu: 123456789 | H10: Hệ thống hiển thị thông báo "Tài khoản không được cấp quyền" | I10: Fail | K10: Sai thông báo "Tài khoản hoặc mật khẩu không đúng"
A11: =$B$2&"-"&ROW()-8 -> Quản lí hóa đơn-3 | B11: UI | D11: Kiểm tra số lượng các items | E11: Đang ở trang admin | F11: 1. View màn hình 2. So sánh với design | H11: 1. Số lượng các item trên màn hình như sau: - button: Chi tiết hóa đơn, Hủy đơn hàng - dropdown: Trạng thái | I11: Pass
A12: =$B$2&"-"&ROW()-8 -> Quản lí hóa đơn-4 | D12: Kiểm tra vị trí, font chữ, size chữ, màu sắc | E12: Đang ở trang admin | F12: 1. Kiểm tra vị trí, font chữ, size chữ, màu sắc | H12: 1. Hiển thị đúng theo design | I12: Pass
A13: =$B$2&"-"&ROW()-8 -> Quản lí hóa đơn-5 | D13: Kiểm tra trạng thái | E13: Đang ở trang admin | F13: 1. Kiểm tra trạng thái các items | H13: Các items đều ở trạng thái enable | I13: Pass
A14: =$B$2&"-"&ROW()-8 -> Quản lí hóa đơn-6 | D14: Kiểm tra giá trị default | E14: Đang ở trang admin | F14: 1. Kiểm tra các giá trị default | H14: Các items hiển thị đúng như trong DB | I14: Pass
A15: =$B$2&"-"&ROW()-8 -> Quản lí hóa đơn-7 | B15: Biz | C15: Xem hóa đơn | D15: Kiểm tra admin xem danh sách hóa đơn | E15: 1. Đang ở trang admin 2. Có ít nhất 1 hóa đơn | F15: 1. Click Hóa đơn trên trang quản trị | H15: Hệ thống hiển thị đầy đủ các thông tin như design | I15: Pass
A16: =$B$2&"-"&ROW()-8 -> Quản lí hóa đơn-8 | D16: Kiểm tra admin xem danh sách hóa đơn rỗng | E16: 1. Đang ở trang admin 2. Không có hóa đơn | F16: 1. Click Hóa đơn trên trang quản trị | H16: Hệ thống hiển thị thông báo "Không có đơn hàng!" | I16: N/A | K16: Không có chức năng xóa ở trang admin
A17: =$B$2&"-"&ROW()-8 -> Quản lí hóa đơn-9 | D17: Lỗi DB khi xem hóa đơn | E17: 1. Đang ở trang admin 2. Có ít nhất 1 hóa đơn | F17: 1. Click Hóa đơn trên trang quản trị | H17: Hệ thống hiển thị thống báo "Lỗi hệ thống" | I17: Untested
A18: =$B$2&"-"&ROW()-8 -> Quản lí hóa đơn-10 | C18: Xem chi tiết hóa đơn | D18: Kiểm tra admin xem chi tiết hóa đơn | E18: 1. Đang ở trang hóa đơn 2. Có ít nhất 1 hóa đơn | F18: 1. Click Chi tiết hóa đơn | H18: 1. Hệ thống hiển thị đầy đủ thông tin theo design 2. Thông tin được hiển thị giống trong DB | I18: Pass
A19: =$B$2&"-"&ROW()-8 -> Quản lí hóa đơn-11 | D19: Kiểm tra admin xem chi tiết hóa đơn khi đã bị hủy | E19: 1. Đang ở trang hóa đơn 2. Có ít nhất 1 hóa đơn | F19: 1. Click Chi tiết hóa đơn | H19: Hệ thống cho phép xem thông tin của sản phẩm đã bị hủy | I19: Pass
A20: =$B$2&"-"&ROW()-8 -> Quản lí hóa đơn-12 | C20: Trạng thái | D20: Kiểm tra admin cập nhật trạng thái đơn hàng | E20: 1. Đang ở trang hóa đơn 2. Có ít nhất 1 hóa đơn | F20: 1. Admin chỉnh sửa trạng thái hóa đơn (Đang giao, Đang chuẩn bị, Đã thanh toán) | H20: Hệ thống sẽ cập nhật trạng thái với trạng thái đã chọn | I20: Pass
A21: =$B$2&"-"&ROW()-8 -> Quản lí hóa đơn-13 | C21: Hủy đơn hàng | D21: Kiểm tra admin hủy đơn hàng thành công | E21: 1. Đang ở trang hóa đơn 2. Có ít nhất 1 hóa đơn | F21: 1. Click Hủy đơn hàng trong Tùy chọn 2. Click OK | H21: 1. Hệ thống sẽ hiển thị thông báo "Bạn có chắc chắn về việc hủy đơn hàng này!" 2. Hệ thống sẽ chỉnh sửa lại trạng thái thành "Đã bị hủy" kèm thông báo "Sửa trạng thái thành công" sau khi click OK | I21: Pass
A22: =$B$2&"-"&ROW()-8 -> Quản lí hóa đơn-14 | D22: Kiểm tra admin hủy đơn hàng thất bại | E22: 1. Đang ở trang hóa đơn 2. Có ít nhất 1 hóa đơn | F22: 1. Click Hủy đơn hàng trong Tùy chọn 2. Click Cancel | H22: 1. Hệ thống sẽ hiển thị thông báo "Bạn có chắc chắn về việc hủy đơn hàng này!" 2. Trạng thái đơn hàng sẽ không bị thay đổi | I22: Pass
A23: =$B$2&"-"&ROW()-8 -> Quản lí hóa đơn-15 | D23: Kiểm tra admin hủy đơn hàng với đơn đã hủy | E23: 1. Đang ở trang hóa đơn 2. Có ít nhất 1 hóa đơn đã bị hủy | F23: 1. Chọn hóa đơn đã bị hủy | H23: Hệ thống ẩn nút Hủy đơn hàng với đơn đã bị hủy | I23: Pass

Sheet Cart
A2: Module Code | B2: Quản lí giỏ hàng | M2: Pass
A3: Test requirement | B3: Hệ thống cho phép khách hàng xem sản phẩm trong giỏ, sửa số lượng, xóa sản phẩm khỏi giỏ hàng | M3: Fail
A4: Tester
A5: Pass | B5: Fail | C5: Untested | D5: N/A | E5: Number of Test cases | M5: Untesed
A6: =COUNTIF(I9:I994,"Pass") -> 21 | B6: =COUNTIF(I9:I994,"Fail") -> 4 | C6: =E6-D6-A6-B6 -> 1 | D6: =COUNTIF(H$9:I$994,"N/A") -> 0 | E6: =COUNTA(A9:A998) -> 26 | M6: N/A
A8: ID | B8: Group Name | C8: Sub Group Name | D8: Test Case Description | E8: Precondition | F8: Test Case Procedure | G8: Test data | H8: Expected Output | I8: Result | J8: Test date | K8: Note
A9: =$B$2&"-"&ROW()-8 -> Quản lí giỏ hàng-1 | B9: Access right | D9: Kiểm tra khách hàng xem giỏ hàng khi chưa đăng nhập | E9: 1. Chưa đăng nhập 2. Có sản phẩm trong giỏ | F9: 1. Mở trang chủ 2. Click vào giỏ hàng | H9: Hệ thống chuyển đến trang giỏ hàng | I9: Pass
A10: =$B$2&"-"&ROW()-8 -> Quản lí giỏ hàng-2 | D10: Kiểm tra khách hàng xem giỏ hàng khi đã đăng nhập | E10: 1. Đã đăng nhập 2. Có sản phẩm trong giỏ | F10: 1. Mở trang chủ 2. Click vào giỏ hàng | G10: tài khoản: test_1 mật khẩu: 123456789 | H10: Hệ thống chuyển đến trang giỏ hàng | I10: Pass
A11: =$B$2&"-"&ROW()-8 -> Quản lí giỏ hàng-3 | B11: UI | D11: Kiểm tra số lượng các items | E11: 1. Đã đăng nhập 2. Có sản phẩm trong giỏ | F11: 1. View màn hình 2. So sánh với design | H11: 1. Số lượng các item trên màn hình như sau: - button: Đặt hàng, CẬP NHẬT GIỎ HÀNG, TIẾP TỤC MUA SẮM | I11: Pass
A12: =$B$2&"-"&ROW()-8 -> Quản lí giỏ hàng-4 | D12: Kiểm tra vị trí, font chữ, size chữ, màu sắc | E12: 1. Đã đăng nhập 2. Có sản phẩm trong giỏ | F12: 1. Kiểm tra vị trí, font chữ, size chữ, màu sắc | H12: 1. Hiển thị đúng theo design | I12: Pass
A13: =$B$2&"-"&ROW()-8 -> Quản lí giỏ hàng-5 | D13: Kiểm tra trạng thái | E13: 1. Đã đăng nhập 2. Có sản phẩm trong giỏ | F13: 1. Kiểm tra trạng thái các items | H13: Các items đều ở trạng thái enable | I13: Pass
A14: =$B$2&"-"&ROW()-8 -> Quản lí giỏ hàng-6 | D14: Kiểm tra giá trị default | E14: 1. Đã đăng nhập 2. Có sản phẩm trong giỏ | F14: 1. Kiểm tra các giá trị default | H14: Các items hiển thị đúng như trong DB | I14: Pass
A15: =$B$2&"-"&ROW()-8 -> Quản lí giỏ hàng-7 | B15: Biz | C15: Xem giỏ hàng | D15: Kiểm tra khách hàng xem giỏ hàng khi có sản phẩm | E15: 1. Đã đăng nhập 2. Có ít nhất 1 sản phẩm trong giỏ | F15: 1. Click icon giỏ hàng | H15: Hệ thống hiển thị đầy đủ thông tin về sản phẩm theo design | I15: Pass
A16: =$B$2&"-"&ROW()-8 -> Quản lí giỏ hàng-8 | D16: Kiểm tra giỏ hàng rỗng | E16: 1. Đã đăng nhập 2. Không có sản phẩm nào trong giỏ | F16: 1. Click icon giỏ hàng | H16: Hệ thống hiển thi thống báo "Chưa có sản phẩm nào trong giỏ hàng" | I16: Pass
A17: =$B$2&"-"&ROW()-8 -> Quản lí giỏ hàng-9 | D17: Lỗi DB khi tải giỏ hàng | E17: 1. Đã đăng nhập 2. Có ít nhất 1 sản phẩm trong giỏ | F17: 1. Click icon giỏ hàng | H17: Hệ thống hiển thị thống báo "Lỗi hệ thống" | I17: Untested
A18: =$B$2&"-"&ROW()-8 -> Quản lí giỏ hàng-10 | C18: Sửa số lượng | D18: Kiểm tra khách hàng tăng số lượng sản phẩm khi click + | E18: 1. Đã đăng nhập 2. Có ít nhất 1 sản phẩm trong giỏ 3. Số lượng sản phẩm < số lượng tồn kho | F18: 1. Click nút (+) của 1 sản phẩm bất kì | G18: Số lượng hiện tại: 1 Số lượng tồn kho: 5 | H18: Hệ thống cập nhật lại số lượng, giá tiền | I18: Pass
A19: =$B$2&"-"&ROW()-8 -> Quản lí giỏ hàng-11 | D19: Kiểm tra khách hàng giảm số lượng sản phẩm khi click - | E19: 1. Đã đăng nhập 2. Có ít nhất 1 sản phẩm trong giỏ 3. Số lượng sản phẩm < số lượng tồn kho | F19: 1. Click nút (-) của 1 sản phẩm bất kì | G19: Số lượng hiện tại: 3 Số lượng tồn kho: 5 | H19: Hệ thống cập nhật lại số lượng, giá tiền | I19: Pass
A20: =$B$2&"-"&ROW()-8 -> Quản lí giỏ hàng-12 | D20: Kiểm tra khách hàng tăng số lượng khi số lượng sản phẩm = số lượng tồn kho | E20: 1. Đã đăng nhập 2. Có ít nhất 1 sản phẩm trong giỏ 3. Số lượng sản phẩm = số lượng tồn kho | F20: 1. Click nút (+) của 1 sản phẩm bất kì | G20: Số lượng hiện tại: 5 Số lượng tồn kho: 5 | H20: Hệ thống sẽ hiển thông báo " Số lượng hàng trong kho không đủ! (Hiện có X) | I20: Pass
A21: =$B$2&"-"&ROW()-8 -> Quản lí giỏ hàng-13 | D21: Kiểm tra khách hàng giảm số lượng sản phẩm khi số lượng =1 | E21: 1. Đã đăng nhập 2. Có ít nhất 1 sản phẩm trong giỏ với số lượng =1 | F21: 1. Click nút (-) của 1 sản phẩm đang có số lượng =1 | G21: Số lượng: 1 | H21: 1. Hệ thống hiển thị thông báo "Bạn có chắc chắn xóa sản phẩm này khỏi giỏ hảng" | I21: Pass
A22: =$B$2&"-"&ROW()-8 -> Quản lí giỏ hàng-14 | C22: Button Cập nhật giỏ hàng | D22: Kiểm tra khách hàng nhập số lượng = 0 | E22: 1. Đã đăng nhập 2. Có ít nhất 1 sản phẩm trong giỏ | F22: 1. Nhấn mũi tên lên xuống hoặc nhập số lượng =0 2. Click button Cập nhật giỏ hàng | G22: Số lượng =0 | H22: 1. Hệ thống hiển thị thông báo "Bạn có chắc chắn xóa sản phẩm này khỏi giỏ hảng" | I22: Fail | K22: Hệ thống sẽ cập nhật lại số lượng và tổng tiền =0đ
A23: =$B$2&"-"&ROW()-8 -> Quản lí giỏ hàng-15 | D23: Kiểm tra khách hàng nhập số lượng là số âm | E23: 1. Đã đăng nhập 2. Có ít nhất 1 sản phẩm trong giỏ | F23: 1. Nhấn mũi tên lên xuống hoặc nhập số lượng là số âm 2. Click button Cập nhật giỏ hàng | G23: Số lượng = -1 | H23: Khi nhập số âm, hệ thống tự động chuyển thành số nguyên dương | I23: Fail | K23: Hệ thống cập nhật lại số lượng và tống tiền là số âm
A24: =$B$2&"-"&ROW()-8 -> Quản lí giỏ hàng-16 | D24: Kiểm tra khách hàng nhập số lượng sản phẩm là số thực | E24: 1. Đã đăng nhập 2. Có ít nhất 1 sản phẩm trong giỏ | F24: 1. Nhấn mũi tên lên xuống hoặc nhập số lượng là số thực 2. Click button Cập nhật giỏ hàng | G24: Số lượng = 1.5 | H24: Khi nhập số thực, hệ thống tự động chuyển thành số nguyên | I24: Fail | K24: Hệ thống cập nhật số lượng là số thực, tổng tiền là số nguyên( sl=1)
A25: =$B$2&"-"&ROW()-8 -> Quản lí giỏ hàng-17 | D25: Kiểm tra khách hàng nhập số lượng là chữ | E25: 1. Đã đăng nhập 2. Có ít nhất 1 sản phẩm trong giỏ | F25: 1. Nhấn mũi tên lên xuống hoặc nhập số lượng là chữ 2. Click button Cập nhật giỏ hàng | G25: Số lượng = a | H25: Hệ thống không cho phép nhập chữ vào trường số lượng | I25: Pass
A26: =$B$2&"-"&ROW()-8 -> Quản lí giỏ hàng-18 | D26: Kiểm tra khách hàng nhập số lượng là kí tự đặc biệt | E26: 1. Đã đăng nhập 2. Có ít nhất 1 sản phẩm trong giỏ | F26: 1. Nhấn mũi tên lên xuống hoặc nhập số lượng là kí tự đặc biệt 2. Click button Cập nhật giỏ hàng | G26: Số lượng = ! | H26: Hệ thống không cho phép nhập kí tự đặc biệt vào trường số lượng | I26: Pass
A27: =$B$2&"-"&ROW()-8 -> Quản lí giỏ hàng-19 | D27: Kiểm tra khách hàng bỏ trống trường số lượng | E27: 1. Đã đăng nhập 2. Có ít nhất 1 sản phẩm trong giỏ | F27: 1. Xóa ô số lượng 2. Click button Cập nhật giỏ hàng | G27: Số lượng = bỏ trống | H27: 1. Hiển thị thông báo "Vui lòng nhập số lượng" | I27: Fail | K27: Hệ thống bỏ trống trường số lượng và tổng tiền là NaN
A28: =$B$2&"-"&ROW()-8 -> Quản lí giỏ hàng-20 | D28: Kiểm tra khách hàng nhập số lượng hợp lệ (số nguyên dương) | E28: 1. Đã đăng nhập 2. Có ít nhất 1 sản phẩm trong giỏ | F28: 1. Nhấn mũi tên lên xuống hoặc nhập số lượng là số hợp lệ 2. Click button Cập nhật giỏ hàng | G28: Số lượng = 2 | H28: Hệ thống cập nhật số lượng, tính lại số tiền, tổng thành tiền và hiển thị lên màn hình | I28: Pass
A29: =$B$2&"-"&ROW()-8 -> Quản lí giỏ hàng-21 | D29: Kiểm tra số lượng tồn kho (số lượng đặt > số lượng tồn kho) | E29: 1. Đã đăng nhập 2. Có ít nhất 1 sản phẩm trong giỏ | F29: 1. Nhập số lượng đặt > số lượng tồn kho 2. Click button Cập nhật giỏ hàng | G29: Số lượng đặt: 100 | H29: Hệ thống hiển thị thông báo "Số lượng hàng trong kho không đủ" | I29: Pass
A30: =$B$2&"-"&ROW()-8 -> Quản lí giỏ hàng-22 | C30: Xóa sản phẩm | D30: Kiểm tra khách hàng xóa 1 sản phẩm trong giỏ hàng | E30: 1. Đã đăng nhập 2. Có ít nhất 1 sản phẩm trong giỏ | F30: 1. Nhấn dấu x ở bên phải sản phẩm 2. Click button OK khi có popup xác nhận | H30: 1. Hệ thống hiển thị thông báo "Bạn có chắc chắn xóa sản phẩm này khỏi giỏ hàng" 2. Sản phẩm sẽ được xóa khỏi session của giỏ hàng | I30: Pass
A31: =$B$2&"-"&ROW()-8 -> Quản lí giỏ hàng-23 | D31: Kiểm tra khách hàng xóa nhiều sản phẩm trong giỏ hàng | E31: 1. Đã đăng nhập 2. Có ít nhất 2 sản phẩm trong giỏ | F31: 1. Nhấn dấu x ở bên phải sản phẩm 2. Click button OK khi có popup xác nhận | H31: 1. Hệ thống hiển thị thông báo cho từng sản phẩm "Bạn có chắc chắn xóa sản phẩm này khỏi giỏ hàng" 2. Sản phẩm sẽ được xóa khỏi session của giỏ hàng | I31: Pass
A32: =$B$2&"-"&ROW()-8 -> Quản lí giỏ hàng-24 | D32: Kiểm tra khách hàng xóa tất cả sản phẩm trong giỏ hàng | E32: 1. Đã đăng nhập 2. Có ít nhất 3 sản phẩm trong giỏ | F32: 1. Nhấn dấu x ở bên phải sản phẩm 2. Click button OK khi có popup xác nhận | H32: 1. Hệ thống hiển thị thông báo cho từng sản phẩm "Bạn có chắc chắn xóa sản phẩm này khỏi giỏ hàng" 2. Sản phẩm sẽ được xóa khỏi session của giỏ hàng 3. Hệ thống sẽ hiển thị "Chưa có sản phẩm nào trong giỏ hàng" | I32: Pass
A33: =$B$2&"-"&ROW()-8 -> Quản lí giỏ hàng-25 | D33: Kiểm tra khách hàng xóa 1 sản phẩm rồi click Hủy | E33: 1. Đã đăng nhập 2. Có ít nhất 1 sản phẩm trong giỏ | F33: 1. Nhấn dấu x ở bên phải sản phẩm 2. Click button Hủy khi có popup xác nhận | H33: 1. Hệ thống hiển thị thông báo "Bạn có chắc chắn xóa sản phẩm này khỏi giỏ hàng" 2. Sản phẩm vẫn trong giỏ hàng sau khi click "Hủy" | I33: Pass
A34: =$B$2&"-"&ROW()-8 -> Quản lí giỏ hàng-26 | C34: Tiếp tục mua sắm | D34: Kiểm tra màn hình quay trở về trang chủ thành công | E34: 1. Đã đăng nhập 2. Đang ở trang giỏ hàng | F34: 1. Click button Tiếp tục mua sắm | H34: Hệ thống chuyển đến màn hình trang chủ | I34: Pass

Sheet Order
A2: Module Code | B2: Đặt hàng | M2: Pass
A3: Test requirement | B3: Hệ thống đặt hàng thành công với các sản phẩm có trong giỏ hàng | M3: Fail
A4: Tester | B4: Vũ Hồng
A5: Pass | B5: Fail | C5: Untested | D5: N/A | E5: Number of Test cases | M5: Untesed
A6: =COUNTIF(I9:I980,"Pass") -> 11 | B6: =COUNTIF(I9:I980,"Fail") -> 0 | C6: =E6-D6-A6-B6 -> 1 | D6: =COUNTIF(H$9:I$980,"N/A") -> 0 | E6: =COUNTA(A9:A984) -> 12 | M6: N/A
A8: ID | B8: Group Name | C8: Sub Group Name | D8: Test Case Description | E8: Precondition | F8: Test Case Procedure | G8: Test data | H8: Expected Output | I8: Result | J8: Test date | K8: Note
A9: =$B$2&"-"&ROW()-8 -> Đặt hàng-1 | B9: Access right | D9: Kiểm tra khách hàng đặt hàng khi chưa đăng nhập | E9: 1. Chưa đăng nhập 2. Đang ở giỏ hàng 3. Có sản phẩm trong giỏ | F9: 1. Click button Đặt hàng | H9: 1. Hệ thống chuyển đến màn hình đăng nhập | I9: Pass
A10: =$B$2&"-"&ROW()-8 -> Đặt hàng-2 | D10: Kiểm tra khách hàng đặt hàng khi đã đăng nhập | E10: 1. Đã đăng nhập 2. Đang ở giỏ hàng 3. Có sản phẩm trong giỏ | F10: 1. Click button Đặt hàng | G10: tài khoản: test_1 mật khẩu: 123456789 | H10: 1. Hệ thống chuyển đến trang thanh toán | I10: Pass
A11: =$B$2&"-"&ROW()-8 -> Đặt hàng-3 | B11: UI | D11: Kiểm tra số lượng các items | E11: 1. Đã đăng nhập 2. Đang ở giỏ hàng 3. Có sản phẩm trong giỏ | F11: 1. View màn hình 2. So sánh với design | H11: 1. Số lượng các item trên màn hình như sau: - text box: Họ tên, Số điện thoại, Địa chỉ, Ghi chú - button: Đặt hàng | I11: Pass
A12: =$B$2&"-"&ROW()-8 -> Đặt hàng-4 | D12: Kiểm tra vị trí, font chữ, size chữ, màu sắc | E12: 1. Đã đăng nhập 2. Đang ở giỏ hàng 3. Có sản phẩm trong giỏ | F12: 1. Kiểm tra vị trí, font chữ, size chữ, màu sắc | H12: 1. Hiển thị đúng theo design | I12: Pass
A13: =$B$2&"-"&ROW()-8 -> Đặt hàng-5 | D13: Kiểm tra trạng thái | E13: 1. Đã đăng nhập 2. Đang ở giỏ hàng 3. Có sản phẩm trong giỏ | F13: 1. Kiểm tra trạng thái các items | H13: Các items đều ở trạng thái enable | I13: Pass
A14: =$B$2&"-"&ROW()-8 -> Đặt hàng-6 | D14: Kiểm tra giá trị default | E14: 1. Đã đăng nhập 2. Đang ở giỏ hàng 3. Có sản phẩm trong giỏ | F14: 1. Kiểm tra các giá trị default | H14: Các items hiển thị đúng như trong DB | I14: Pass
A15: =$B$2&"-"&ROW()-8 -> Đặt hàng-7 | B15: Validation | C15: Thông tin nhận hàng | D15: Kiểm tra khách hàng không thay đổi thông tin trước khi đặt hàng | E15: 1. Đã đăng nhập 2. Đang ở trang đặt hàng | F15: 1. Giữ nguyên thông tin nhận hàng 2. Click button Đặt hàng | G15: Họ tên: Thử Số điện thoại: 0123654789 Địa chỉ: Mão Điền Ghi chú: Che tên sản phẩm | H15: Hệ thống lấy tên tài khoản, số điện thoại và địa chỉ mặc định | I15: Pass
A16: =$B$2&"-"&ROW()-8 -> Đặt hàng-8 | D16: Kiểm tra khách hàng thay đổi thông tin nhận hàng trước khi đặt | E16: 1. Đã đăng nhập 2. Đang ở trang đặt hàng | F16: 1. Sửa thông tin nhận hàng 2. Click button Đặt hàng | G16: Họ tên: Hồng Số điện thoại: 0123654789 Địa chỉ: Mão Điền Ghi chú: Che tên sản phẩm | H16: 1. Hệ thống cho phép thay đổi thông tin 2. Hệ thống lưu thông tin vào bảng HOADON | I16: Pass
A17: =$B$2&"-"&ROW()-8 -> Đặt hàng-9 | D17: Kiểm tra khách hàng bỏ trống trường họ tên/ số điện thoại/địa chỉ | E17: 1. Đã đăng nhập 2. Đang ở trang đặt hàng | F17: 1. Bỏ trống trường họ tên/sdt/địa chỉ 2. Click button Đặt hàng | G17: Họ tên: Bỏ trống Số điện thoại: Bỏ trống Địa chỉ: Bỏ trống | H17: Hệ thống hiển thị thông báo "Vui lòng điền thông tin vào đây" | I17: Pass
A18: =$B$2&"-"&ROW()-8 -> Đặt hàng-10 | B18: Biz | C18: Button Đặt hàng | D18: Kiểm tra khách hàng đặt hàng thành công | E18: 1. Đã đăng nhập 2. Đang ở trang giỏ hàng 3. Giỏ hàng có ít nhất 1 sản phẩm | F18: 1. Click button Đặt hàng 2. Điền thông tin và click button Đặt hàng ở trang thanh toán | H18: 1. Hệ thống hiển thị thông tin hóa đơn 2. Sản phẩm sẽ biến mất khỏi giỏ hàng | I18: Pass
A19: =$B$2&"-"&ROW()-8 -> Đặt hàng-11 | D19: Kiểm tra khách hàng đặt hàng khi giỏ hàng rỗng | E19: 1. Đã đăng nhập 2. Đang ở trang giỏ hàng 3. Giỏ hàng không có sản phẩm | F19: 1. Click button Đặt hàng 2. Điền thông tin và click button Đặt hàng ở trang thanh toán | H19: 1. Hệ thống không chuyển sang trang thanh toán | I19: Pass
A20: =$B$2&"-"&ROW()-8 -> Đặt hàng-12 | D20: Lõi DB khi đặt hàng | E20: Khách hàng đã đăng nhập và đang ở giỏ hàng, tồn tại ít nhất 1 sản phẩm trong giỏ hàng | F20: 1. Click button Đặt hàng | H20: Hệ thống hiển thị thông báo "Lỗi hệ thống" | I20: Untesed

Sheet Register
A2: Module Code | B2: Đăng ký tài khoản | M2: Pass
A3: Test requirement | B3: Hệ thống tạo tài khoản thành công khi nhập các thông tin hợp lệ | M3: Fail
A4: Tester
A5: Pass | B5: Fail | C5: Untested | D5: N/A | E5: Number of Test cases | M5: Untested
A6: =COUNTIF(I9:I1041,"Pass") -> 39 | B6: =COUNTIF(I9:I1041, "Fail") -> 17 | C6: =COUNTIF(I9:I1041, "Untested") -> 1 | D6: =COUNTIF(H$9:I$1041,"N/A") -> 0 | E6: =COUNTA(A9:A1045) -> 57 | M6: N/A
A8: ID | B8: Group Name | C8: Sub Group Name | D8: Test Case Description | E8: Precondition | F8: Test Case Procedure | G8: Test data | H8: Expected Output | I8: Result | J8: Test date | K8: Note
A9: =$B$2&"-"&ROW()-8 -> Đăng ký tài khoản-1 | B9: Access right | D9: Kiểm tra user đăng ký với tư cách là khách hàng | E9: 1. Chưa đăng nhập 2. Tài khoản chưa tồn tại | F9: 1. Mở trang chủ 2. Click vào Tài khoản 3. Click vào Đăng ký | H9: 1. Hiển thị lên màn hình form đăng ký | I9: Pass
A10: =$B$2&"-"&ROW()-8 -> Đăng ký tài khoản-2 | D10: Kiểm tra quyền truy cập khi đã đăng nhập | E10: Đã đăng nhập | F10: 1. Mở trang chủ 2. Đăng nhập tài khoản 3. Cố truy cập trang đăng ký | H10: Hệ thống sẽ không hiển thị chức năng Đăng ký | I10: Pass
A11: =$B$2&"-"&ROW()-8 -> Đăng ký tài khoản-3 | B11: UI | D11: Kiểm tra số lượng các items | E11: 1. Đang ở màn hình đăng ký | F11: 1. View màn hình 2. So sánh với design | H11: 1. Số lượng các item trên màn hình như sau: - text box: Họ và tên, Số điện thoại, Địa chỉ, Giới tính, Email, Tài khoản, Mật khẩu, Xác nhận mật khẩu - button: Đăng ký - radio: Nam, Nữ | I11: Pass
A12: =$B$2&"-"&ROW()-8 -> Đăng ký tài khoản-4 | D12: Kiểm tra vị trí, font chữ, size chữ, màu sắc | E12: 1. Đang ở màn hình đăng ký | F12: 1. Kiểm tra vị trí, font chữ, size chữ, màu sắc | H12: 1. Hiển thị đúng theo design | I12: Pass
A13: =$B$2&"-"&ROW()-8 -> Đăng ký tài khoản-5 | D13: Kiểm tra trạng thái | E13: 1. Đang ở màn hình đăng ký | F13: 1. Kiểm tra trạng thái các items | H13: Các items đều ở trạng thái enable | I13: Pass
A14: =$B$2&"-"&ROW()-8 -> Đăng ký tài khoản-6 | D14: Kiểm tra giá trị default | E14: 1. Đang ở màn hình đăng ký | F14: 1. Kiểm tra các giá trị default | H14: Các text box đều hiển thị trắng | I14: Pass
A15: =$B$2&"-"&ROW()-8 -> Đăng ký tài khoản-7 | B15: Validation | C15: Họ tên | D15: Bỏ trống | E15: 1. Đang ở màn hình đăng ký | F15: 1. Bỏ trống trường họ tên 2. Các trường còn lại nhập hợp lệ 3. Click button Đăng ký | G15: Họ tên: | H15: Hệ thống hiển thị thông báo : "Vui lòng nhập thông tin vào đây" | I15: Pass | K15: Châp nhận Please fill out this field (do cài đặt tùy Chrome)
A16: =$B$2&"-"&ROW()-8 -> Đăng ký tài khoản-8 | D16: Kiểm tra khách hàng nhập họ tên là chữ thường | E16: 1. Đang ở màn hình đăng ký | F16: 1. Họ tên: nhập chữ thường 2. Các trường còn lại nhập hợp lệ 3. Click button Đăng ký | G16: Họ tên: hồng | H16: Hệ thống cho phép nhập họ tên là chữ thường | I16: Pass
A17: =$B$2&"-"&ROW()-8 -> Đăng ký tài khoản-9 | D17: Kiểm tra khách hàng nhập họ tên là chữ in hoa | E17: 1. Đang ở màn hình đăng ký | F17: 1. Họ tên: nhập chữ in hoa 2. Các trường còn lại nhập hợp lệ 3. Click button Đăng ký | G17: Họ tên: HỒNG | H17: Hệ thống cho phép nhập họ tên là chữ in hoa | I17: Pass
A18: =$B$2&"-"&ROW()-8 -> Đăng ký tài khoản-10 | D18: Kiểm tra khách hàng nhập họ tên là chữ thường + in hoa | E18: 1. Đang ở màn hình đăng ký | F18: 1. Họ tên: nhập chữ thường và chữ in hoa 2. Các trường còn lại nhập hợp lệ 3. Click button Đăng ký | G18: Họ tên: HỒNg | H18: Hệ thống cho phép nhập họ tên là chữ in hoa + chữ thường | I18: Pass
A19: =$B$2&"-"&ROW()-8 -> Đăng ký tài khoản-11 | D19: Kiểm tra khách hàng nhập họ tên là số | E19: 1. Đang ở màn hình đăng ký | F19: 1. Họ tên: nhập số 2. Các trường còn lại nhập hợp lệ 3. Click button Đăng ký | G19: Họ tên: 123 | H19: 1. Hệ thống không cho phép nhập họ tên là số 2. Hệ thống hiển thị thông báo "Đăng ký không thành công. Thử lại sau !" | I19: Fail | K19: Hệ thống cho phép đăng ký
A20: =$B$2&"-"&ROW()-8 -> Đăng ký tài khoản-12 | D20: Kiểm tra khách hàng nhập họ tên là kí tự đặc biệt | E20: 1. Đang ở màn hình đăng ký | F20: 1. Họ tên: nhập kí tự đặc biệt 2. Các trường còn lại nhập hợp lệ 3. Click button Đăng ký | G20: Họ tên: !@# | H20: 1. Hệ thống không cho phép nhập họ tên là kí tự đặc biệt 2. Hệ thống hiển thị thống báo "Đăng ký không thành công. Thử lại sau !" | I20: Fail | K20: Hệ thống cho phép đăng ký
A21: =$B$2&"-"&ROW()-8 -> Đăng ký tài khoản-13 | D21: Kiểm tra khách hàng nhập họ tên là chữ thường + số | E21: 1. Đang ở màn hình đăng ký | F21: 1. Nhập họ tên có cả chữ và số 2. Các trường còn lại nhập hợp lệ 3. Click button Đăng ký | G21: Họ tên: hồng12 | H21: Hệ thống cho phép nhập họ tên là chữ thường+ số | I21: Pass
A22: =$B$2&"-"&ROW()-8 -> Đăng ký tài khoản-14 | D22: Kiểm tra khách hàng nhập họ tên là chữ thường + kí tự đặc biệt | E22: 1. Đang ở màn hình đăng ký | F22: 1. Nhập họ tên có cả chữ và kí tự đặc biệt 2. Các trường còn lại nhập hợp lệ 3. Click button Đăng ký | G22: Họ tên: hồng@# | H22: 1. Hệ thống không cho phép nhập họ tên là chữ thường + kí tự đặc biệt 2. Hệ thống hiển thị thống báo "Đăng ký không thành công. Thử lại sau !" | I22: Fail | K22: Hệ thống cho phép đăng ký
A23: =$B$2&"-"&ROW()-8 -> Đăng ký tài khoản-15 | D23: Kiểm tra khách hàng nhập họ tên chứa khoảng trắng | E23: 1. Đang ở màn hình đăng ký | F23: 1. Nhập họ tên chứa khoảng trắng 2. Các trường còn lại nhập hợp lệ 3. Click button Đăng ký | G23: Họ tên: <khoảng trắng> hồng | H23: Hệ thống cho phép nhập họ tên chứa khoảng trắng | I23: Pass
A24: =$B$2&"-"&ROW()-8 -> Đăng ký tài khoản-16 | C24: Số điện thoại | D24: Bỏ trống | E24: 1. Đang ở màn hình đăng ký | F24: 1. Bỏ trống trường số điện thoại 2. Các trường khác nhập giá trị hợp lệ 3. Click button Đăng ký | G24: Số điện thoại: <trống> | H24: Hệ thống hiển thị thông báo : "Vui lòng nhập thông tin vào đây" | I24: Pass
A25: =$B$2&"-"&ROW()-8 -> Đăng ký tài khoản-17 | D25: Kiểm tra khách hàng nhập số điện thoại là chữ/kí tự đặc biệt | E25: 1. Đang ở màn hình đăng ký | F25: 1. Nhập số điện thoại là chữ/ kí tự đặc biệt 2. Các trường khác nhập giá trị hợp lệ 3. Click button Đăng ký | G25: Số điện thoại: điện!@ | H25: 1. Hệ thống hiển thị thông báo : "Đăng ký không thành công. Thử lại sau !" | I25: Fail | K25: Hệ thống cho phép đăng ký
A26: =$B$2&"-"&ROW()-8 -> Đăng ký tài khoản-18 | D26: Kiểm tra khách hàng nhập số điện thoại có khoảng trắng | E26: 1. Đang ở màn hình đăng ký | F26: 1. Nhập số điện thoại chứa khoảng trắng 2. Các trường khác nhập giá trị hợp lệ 3. Click button Đăng ký | G26: Số điện thoại: 0123 456 789 | H26: 1. Hệ thống hiển thị thông báo : "Đăng ký không thành công. Thử lại sau !" | I26: Pass
A27: =$B$2&"-"&ROW()-8 -> Đăng ký tài khoản-19 | D27: Kiểm tra khách hàng nhập số điện thoại là số khác 0 ở đầu | E27: 1. Đang ở màn hình đăng ký | F27: 1. Nhập số điện thoại khác 0 ở đầu 2. Các trường khác nhập giá trị hợp lệ 3. Click button Đăng ký | G27: Số điện thoại: 1234567899 | H27: Hệ thống hiển thị thông báo : "Đăng ký không thành công. Thử lại sau !" | I27: Fail | K27: Cho phép nhập số khác 0
A28: =$B$2&"-"&ROW()-8 -> Đăng ký tài khoản-20 | D28: Kiểm tra khách hàng nhập số điện thoại <10 kí tự | E28: 1. Đang ở màn hình đăng ký | F28: 1. Nhập số điện thoại có 9 kí tự 2. Các trường khác nhập giá trị hợp lệ 3. Click button Đăng ký | G28: Số điện thoại: 012345678 | H28: Hệ thống hiển thị thông báo : "Đăng ký không thành công. Thử lại sau !" | I28: Fail | K28: Hệ thống cho phép đăng ký
A29: =$B$2&"-"&ROW()-8 -> Đăng ký tài khoản-21 | D29: Kiểm tra khách hàng nhập số điện thoại =10 kí tự | E29: 1. Đang ở màn hình đăng ký | F29: 1. Nhập số điện thoại có 10 kí tự 2. Các trường khác nhập giá trị hợp lệ 3. Click button Đăng ký | G29: Số điện thoại: 0123456789 | H29: 1. Hệ thống cho phép nhập số điện thoại đủ 10 kí tự 2. Hệ thống không hiển thị thông báo | I29: Pass
A30: =$B$2&"-"&ROW()-8 -> Đăng ký tài khoản-22 | D30: Kiểm tra khách hàng nhập số điện thoại > 10 kí tự | E30: 1. Đang ở màn hình đăng ký | F30: 1. Nhập số điện thoại có 11 kí tự 2. Các trường khác nhập giá trị hợp lệ 3. Click button Đăng ký | G30: Số điện thoại: 01234567899 | H30: Hệ thống hiển thị thông báo : "Đăng ký không thành công. Thử lại sau !" | I30: Fail | K30: Hệ thống cho phép đăng ký
A31: =$B$2&"-"&ROW()-8 -> Đăng ký tài khoản-23 | C31: Email | D31: Bỏ trống | E31: 1. Đang ở màn hình đăng ký | F31: 1. Bỏ trống trường Email 2. Các trường khác nhập giá trị hợp lệ 3. Click button Đăng ký | G31: Email: <trống> | H31: Hệ thống hiển thị thông báo : "Vui lòng nhập thông tin vào đây" | I31: Pass
A32: =$B$2&"-"&ROW()-8 -> Đăng ký tài khoản-24 | D32: Kiểm tra khách hàng nhập email thiếu @ | E32: 1. Khách hàng đang ở màn hình đăng ký 2. Tồn tại email: hong@gmail.com | F32: 1. Nhập email thiếu @ 2. Các trường khác nhập giá trị hợp lệ 3. Click button Đăng ký | G32: Email: honggmail.com | H32: Hệ thống hiển thị thông báo : "Đăng ký không thành công. Thử lại sau !" | I32: Fail | K32: Sai thông báo
A33: =$B$2&"-"&ROW()-8 -> Đăng ký tài khoản-25 | D33: Kiểm tra khách hàng nhập email thiếu (.) | E33: 1. Khách hàng đang ở màn hình đăng ký 2. Tồn tại email: hong@gmail.com | F33: 1. Nhập email thiếu (.) 2. Các trường khác nhập giá trị hợp lệ 3. Click button Đăng ký | G33: hong@gmailcom | H33: Hệ thống hiển thị thông báo : "Đăng ký không thành công. Thử lại sau !" | I33: Fail | K33: Hệ thống cho phép đăng ký
A34: =$B$2&"-"&ROW()-8 -> Đăng ký tài khoản-26 | D34: Kiểm tra khách hàng nhập email không có local | E34: 1. Đang ở màn hình đăng ký | F34: 1. Nhập email thiếu local 2. Các trường khác nhập giá trị hợp lệ 3. Click button Đăng ký | G34: @gmail.com' | H34: Hệ thống hiển thị thông báo : "Đăng ký không thành công. Thử lại sau !" | I34: Fail | K34: Sai thông báo
A35: =$B$2&"-"&ROW()-8 -> Đăng ký tài khoản-27 | D35: Kiểm tra khách hàng nhập email không có TLD | E35: 1. Đang ở màn hình đăng ký | F35: 1. Nhập email không có TLD 2. Các trường khác nhập giá trị hợp lệ 3. Click button Đăng ký | G35: hong@gmail | H35: Hệ thống hiển thị thông báo : "Đăng ký không thành công. Thử lại sau !" | I35: Fail | K35: Hệ thống cho phép đăng ký
A36: =$B$2&"-"&ROW()-8 -> Đăng ký tài khoản-28 | D36: Kiểm tra khách hàng email hợp lệ | E36: 1. Khách hàng đang ở màn hình đăng ký 2. Tồn tại email: hong@gmail.com | F36: 1. Nhập email hợp lệ 2. Các trường khác nhập giá trị hợp lệ 3. Click button Đăng ký | G36: Email: hong@gmail.com | H36: Hệ thống không hiển thị thông báo lỗi | I36: Pass
A37: =$B$2&"-"&ROW()-8 -> Đăng ký tài khoản-29 | C37: Mật khẩu | D37: Bỏ trống | E37: 1. Đang ở màn hình đăng ký | F37: 1. Bỏ trống trường mật khẩu 2. Các trường khác nhập giá trị hợp lệ 3. Click button Đăng ký | G37: Mật khẩu: <trống> | H37: Hệ thống hiển thị thông báo : "Vui lòng nhập thông tin vào đây" | I37: Pass
A38: =$B$2&"-"&ROW()-8 -> Đăng ký tài khoản-30 | D38: Kiểm tra khách hàng nhập mật khẩu hợp lệ | E38: 1. Đang ở màn hình đăng ký | F38: 1. Nhập mật khẩu hợp lệ > 6 kí tự 2. Các trường khác nhập giá trị hợp lệ 3. Click button Đăng ký | G38: Mật khẩu: 123456 | H38: Hệ thống không hiển thị thông báo lỗi | I38: Pass
A39: =$B$2&"-"&ROW()-8 -> Đăng ký tài khoản-31 | C39: Xác nhận mật khẩu | D39: Bỏ trống | E39: 1. Đang ở màn hình đăng ký 2. Đã nhập mật khẩu | F39: 1. Bỏ trống trường xác nhận mật khẩu 2. Các trượng khác nhập giá trị hợp lệ 3. Click button Đăng ký | G39: Mật khẩu: 123456 Xác nhận mật khẩu: <trống> | H39: Hệ thống hiển thị thông báo : "Vui lòng nhập thông tin vào đây" | I39: Pass
A40: =$B$2&"-"&ROW()-8 -> Đăng ký tài khoản-32 | D40: Kiểm tra khách hàng nhập mật khẩu không khớp xác nhận | E40: 1. Đang ở màn hình đăng ký 2. Đã nhập mật khẩu | F40: 1. Nhập mật khẩu và xác nhận mật khẩu khác nhau 2. Các trượng khác nhập giá trị hợp lệ 3. Click button Đăng ký | G40: Mật khẩu: 123456 Xác nhận mật khẩu: 1234567 | H40: Hệ thống hiển thị thông báo "Mật khẩu không khớp" | I40: Pass
A41: =$B$2&"-"&ROW()-8 -> Đăng ký tài khoản-33 | D41: Kiểm tra khách hàng nhập mật khẩu khớp với xác nhận | E41: 1. Đang ở màn hình đăng ký 2. Đã nhập mật khẩu | F41: 1. Nhập mật khẩu và xác nhận mật khẩu trùng nhau 2. Các trượng khác nhập giá trị hợp lệ 3. Click button Đăng ký | G41: Mật khẩu: 1234567 Xác nhận mật khẩu: 1234567 | H41: Hệ thống không hiển thị thông báo lỗi | I41: Pass
A42: =$B$2&"-"&ROW()-8 -> Đăng ký tài khoản-34 | C42: Tài khoản | D42: Bỏ trống | E42: Khách hàng đang ở form đăng ký | F42: 1. Bỏ trống trường tài khoản 2. Các trường khác nhập giá trị hợp lệ 3. Click button Đăng ký | G42: Tài khoản: bỏ trống | H42: Hệ thống hiển thị thông báo : "Vui lòng nhập thông tin vào đây" | I42: Pass
...

Sheet Product_detail
A2: Module Code | B2: Xem chi tiết sản phẩm | M2: Pass
A3: Test requirement | B3: Hệ thống hiển thị thông tin chi tiết sản phẩm khi click vào một sản phẩm bất kỳ. Có thể: - Xem đánh giá - Thêm sản phẩm vào giỏ | M3: Fail
A4: Tester | B4: Vũ Hồng
A5: Pass | B5: Fail | C5: Untested | D5: N/A | E5: Number of Test cases | M5: Untested
A6: =COUNTIF(I9:I994,"Pass") -> 10 | B6: =COUNTIF(I9:I994,"Fail") -> 5 | C6: =E6-D6-A6-B6 -> 1 | D6: =COUNTIF(H$9:I$994,"N/A") -> 0 | E6: =COUNTA(A9:A998) -> 16 | M6: N/A
A8: ID | B8: Group Name | C8: Sub Group Name | D8: Test Case Description | E8: Precondition | F8: Test Case Procedure | G8: Test data | H8: Expected Output | I8: Result | J8: Test date | K8: Note
A9: =$B$2&"-"&ROW()-8 -> Xem chi tiết sản phẩm-1 | B9: Access right | D9: Kiểm tra khách hàng xem chi tiết sản phẩm khi chưa đăng nhập | E9: Chưa đăng nhập | F9: 1. Mở trang chủ 2. Click vào 1 sản phẩm bất kì | H9: 1. Cho phép xem chi tiết sản phẩm khi chưa đăng nhập 2. Hệ thống chuyển đến trang xem chi tiết sản phẩm | I9: Pass
A10: =$B$2&"-"&ROW()-8 -> Xem chi tiết sản phẩm-2 | D10: Kiểm tra khách hàng xem chi tiết khi đã đăng nhập | E10: Đã đăng nhập | F10: 1. Mở trang chủ 2. Click vào 1 sản phẩm bất kì | G10: tài khoản: test_1 mật khẩu: 123456789 | H10: 1. Hệ thống chuyển đến trang xem chi tiết sản phẩm | I10: Pass
A11: =$B$2&"-"&ROW()-8 -> Xem chi tiết sản phẩm-3 | B11: UI | D11: Kiểm tra số lượng các items | E11: 1. Khách hàng đã đăng nhập 2. Đang ở trang xem chi tiết sản phẩm | F11: 1. View màn hình 2. So sánh với design | H11: 1. Số lượng các item trên màn hình như sau: - button: Thêm Vào Giỏ - dropdown: Size | I11: Pass
A12: =$B$2&"-"&ROW()-8 -> Xem chi tiết sản phẩm-4 | D12: Kiểm tra vị trí, font chữ, size chữ, màu sắc | E12: 1. Khách hàng đã đăng nhập 2. Đang ở trang xem chi tiết sản phẩm | F12: 1. Kiểm tra vị trí, font chữ, size chữ, màu sắc | H12: Hiển thị đúng theo design | I12: Pass
A13: =$B$2&"-"&ROW()-8 -> Xem chi tiết sản phẩm-5 | D13: Kiểm tra trạng thái | E13: 1. Khách hàng đã đăng nhập 2. Đang ở trang xem chi tiết sản phẩm | F13: 1. Kiểm tra trạng thái các items | H13: 1. Sản phẩm còn hàng: Item ở trạng thái enable 2. Sản phẩm hết hàng, hết size/màu: Item ở trạng thái disable | I13: Fail | K13: Khi hết hàng, hết size/màu, button ở trạng thái enable
A14: =$B$2&"-"&ROW()-8 -> Xem chi tiết sản phẩm-6 | D14: Kiểm tra giá trị default | E14: 1. Khách hàng đã đăng nhập 2. Đang ở trang xem chi tiết sản phẩm | F14: 1. Kiểm tra các giá trị default | H14: Các giá trị default hiển thị theo đúng như trong DB | I14: Pass
A15: =$B$2&"-"&ROW()-8 -> Xem chi tiết sản phẩm-7 | B15: Biz | C15: Xem chi tiết sản phẩm | D15: Kiểm tra khách hàng xem chi tiết sản phẩm khi click vào sản phẩm còn hàng | E15: Tồn tại sản phẩm và sản phẩm còn hàng | F15: 1. Click vào 1 sản phẩm bất kì | G15: Sản phẩm: Áo phông nữ in họa tiết | H15: 1. Hiển thị thông tin chi tiết sản phẩm lên màn hình 2. Dữ liệu hiển thị đúng như trong DB | I15: Pass
A16: =$B$2&"-"&ROW()-8 -> Xem chi tiết sản phẩm-8 | D16: Kiểm tra khách hàng xem chi tiết sản phẩm khi click vào sản phẩm hết hàng | E16: Tồn tài sản phẩm và số lượng =0 | F16: 1. Click vào 1 sản phẩm bất kì | G16: Sản phẩm: Quần jeans nữ ôm body | H16: 1. Hệ thống hiển thị đầy đủ thông tin về sản phẩm 2. Hiển thị thông báo "Hết hàng! Hãy chọn sản phẩm khác" | I16: Fail | K16: 1. Sai thông báo: Hết hàng! Hãy chọn kích cỡ khác 2. Button enable
A17: =$B$2&"-"&ROW()-8 -> Xem chi tiết sản phẩm-9 | D17: Kiểm tra khách hàng chọn kích cỡ/màu sắc đã hết hàng | E17: Tồn tài sản phẩm và hết size XXXL màu xám | F17: 1. Click vào 1 sản phẩm bất kì | G17: Sản phẩm: Áo phông nam trơn | H17: 1. Hệ thống hiển thị đầy đủ thông tin về sản phẩm 2. Hiển thị thông báo "Số lượng hàng trong kho không đủ" 3. Button Thêm Vào Giỏ disable với những sản phẩm hết | I17: Fail | K17: 1. Button enable
A18: =$B$2&"-"&ROW()-8 -> Xem chi tiết sản phẩm-10 | D18: Lỗi DB | E18: Tồn tại sản phẩm và sản phẩm còn hàng DB đang lỗi | F18: 1. Click vào 1 sản phẩm bất kì | G18: Sản phẩm: Áo sơ mi | H18: Hệ thống hiển thị thông báo "Lỗi hệ thống" | I18: Untested
A19: =$B$2&"-"&ROW()-8 -> Xem chi tiết sản phẩm-11 | C19: Xem đánh giá | D19: Kiểm tra sản phẩm có đánh giá | E19: Đang ở trang xem chi tiết sản phẩm | F19: 1. Click vào 1 sản phẩm bất kì | G19: Sản phẩm: Áo sơ mi nam trơn | H19: Hệ thống hiển thị đầy đủ thông tin người đánh giá, bình luận, ngày tạo | I19: Pass
A20: =$B$2&"-"&ROW()-8 -> Xem chi tiết sản phẩm-12 | D20: Kiểm tra sản phẩm không có đánh giá | E20: Đang ở trang xem chi tiết sản phẩm | F20: 1. Click vào 1 sản phẩm bất kì | G20: Sản phẩm: Áo phông nữ in họa tiết | H20: Hệ thống hiển thị "Chưa có đánh giá nào" | I20: Pass
A21: =$B$2&"-"&ROW()-8 -> Xem chi tiết sản phẩm-13 | C21: Thêm Vào Giỏ | D21: Kiểm tra khách hàng thêm vào giỏ thành công | E21: 1. Khách hàng đã đăng nhập 2. Đang ở trang xem chi tiết sản phẩm | F21: 1. Click button Thêm Vào Giỏ | G21: Áo ba lỗ | H21: 1. Hệ thống thêm sản phẩm thành công vào giỏ hàng 2. Hiển thị thông báo thành công với nội dung "Xem chi tiết tại giỏ <3" | I21: Pass
A22: =$B$2&"-"&ROW()-8 -> Xem chi tiết sản phẩm-14 | D22: Kiểm tra khách hàng thêm vào giỏ khi sản phẩm hết hàng | E22: 1. Khách hàng đã đăng nhập 2. Đang ở trang xem chi tiết sản phẩm | F22: 1. Chọn sản phẩm đang hết hàng 2. Click button Thêm Vào Giỏ | G22: Quần jean nữ ôm body | H22: 1. Hệ thống hiển thị thông báo "Hết hàng! Vui lòng chọn sản phẩm khác" 2. Button Thêm Vào Giỏ sẽ disable | I22: Fail | K22: 1. Sai thông báo "Hết hàng! Vui lòng chọn kích cỡ khác" 2. Button enable
A23: =$B$2&"-"&ROW()-8 -> Xem chi tiết sản phẩm-15 | D23: Kiểm tra khách hàng thêm vào giỏ khi sản phẩm hết size/màu | E23: 1. Khách hàng đã đăng nhập 2. Đang ở trang xem chi tiết sản phẩm | F23: 1. Chọn sản phẩm đang hết size/màu 2. Click button Thêm Vào Giỏ | G23: Áo phông nam trơn, hết size XXXL | H23: 1 Hiển thị thông báo "Số lượng hàng trong kho không đủ" 2. Button Thêm Vào Giỏ disable với những sản phẩm hết | I23: Fail | K23: 1. Button enable
A24: =$B$2&"-"&ROW()-8 -> Xem chi tiết sản phẩm-16 | D24: Kiểm tra khách hàng thêm số lượng lớn hơn số lượng tồn kho | E24: 1. Khách hàng đã đăng nhập 2. Đang ở trang xem chi tiết sản phẩm | F24: 1. Tăng số lượng lớn hơn số lượng tồn kho 2. Click button Thêm Vào Giỏ | G24: Số lượng: 1000 | H24: 1. Hệ thống hiển thi thông báo "Số lượng hàng trong kho không đủ" 2. Sản phẩm không được thêm vào giỏ hàng | I24: Pass

Sheet Category
A2: Module Code | B2: Xem danh mục sản phẩm | M2: Pass
A3: Test requirement | B3: Hệ thống hiển thị tất cả các danh mục đang có khi click vào Sản phẩm trên thanh menu | M3: Fail
A4: Tester | B4: Vũ Hồng
A5: Pass | B5: Fail | C5: Untested | D5: N/A | E5: Number of Test cases | M5: Untested
A6: =COUNTIF(I9:I993,"Pass") -> 7 | B6: =COUNTIF(I9:I993,"Fail") -> 0 | C6: =E6-D6-A6-B6 -> 2 | D6: =COUNTIF(H$9:I$993,"N/A") -> 0 | E6: =COUNTA(A9:A997) -> 9 | M6: N/A
A8: ID | B8: Group Name | C8: Sub Group Name | D8: Test Case Description | E8: Precondition | F8: Test Case Procedure | G8: Test data | H8: Expected Output | I8: Result | J8: Test date | K8: Note
A9: =$B$2&"-"&ROW()-8 -> Xem danh mục sản phẩm-1 | B9: Access right | D9: Kiểm tra khách hàng xem danh mục sản phẩm khi chưa đăng nhập | E9: Chưa đăng nhập | F9: 1. Mở trang chủ 2. Hover Sản phẩm trên menu | H9: 1. Cho phép xem danh mục khi chưa đăng nhập 2. Hiển thị tất cả các danh mục đang có | I9: Pass
A10: =$B$2&"-"&ROW()-8 -> Xem danh mục sản phẩm-2 | D10: Kiểm tra khách hàng xem danh mục khi đã đăng nhập | E10: Đã đăng nhập | F10: 1. Mở trang chủ 2. Click Sản phẩm trên menu | G10: tài khoản: test_1 mật khẩu: 123456789 | H10: Hệ thống cho phép xem danh mục | I10: Pass
A11: =$B$2&"-"&ROW()-8 -> Xem danh mục sản phẩm-3 | B11: UI | D11: Kiểm tra số lượng các items | F11: 1. View màn hình 2. So sánh với design | H11: 1. Số lượng các item hiển thị theo design | I11: Pass
A12: =$B$2&"-"&ROW()-8 -> Xem danh mục sản phẩm-4 | D12: Kiểm tra vị trí, font chữ, size chữ, màu sắc | F12: 1. Kiểm tra vị trí, font chữ, size chữ, màu sắc | H12: 1. Hiển thị theo đúng design | I12: Pass
A13: =$B$2&"-"&ROW()-8 -> Xem danh mục sản phẩm-5 | D13: Kiểm tra trạng thái | F13: 1. Kiểm tra trạng thái các items | H13: Các item đều ở trạng thái enable | I13: Pass
A14: =$B$2&"-"&ROW()-8 -> Xem danh mục sản phẩm-6 | D14: Kiểm tra giá trị default | F14: 1. Kiểm tra các giá trị default | H14: Các giá trị default hiển thị theo đúng trong DB | I14: Pass
A15: =$B$2&"-"&ROW()-8 -> Xem danh mục sản phẩm-7 | B15: Biz | C15: Xem danh mục | D15: Kiểm tra khách hàng xem danh sách danh mục đang có | E15: Có ít nhất 1 danh mục | F15: 1. Hover vào Sản phẩm trên thanh menu | H15: 1. Hệ thống hiển thị danh mục đang có lên màn hình 2. Các thông tin hiện thị đúng như trong DB | I15: Pass
A16: =$B$2&"-"&ROW()-8 -> Xem danh mục sản phẩm-8 | D16: Kiểm tra khách hàng xem danh mục rỗng | E16: Danh mục rỗng | F16: 1. Hover vào Sản phẩm trên thanh menu | H16: Hệ thống sẽ hiển thị thông báo "Chưa có danh mục nào!" | I16: Untested | K16: Cần ngắt/xóa hết danh mục trong DB
A17: =$B$2&"-"&ROW()-8 -> Xem danh mục sản phẩm-9 | D17: Lỗi DB khi xem danh mục | E17: 1. Có ít nhất 1 danh mục 2. Lỗi DB | F17: 1. Hover vào Sản phẩm trên thanh menu | H17: Hiển thị thông báo "Lỗi hệ thống" | I17: Untested | K17: Cần giả lập DB

Sheet Search
A2: Module Code | B2: Tìm kiếm | M2: Pass
A3: Test requirement | B3: Người dùng nhập từ khóa vào thanh tìm kiếm trên menu - Nếu đúng: hiển thị sản phẩm - Nếu sai: hiển thị thông báo | M3: Fail
A4: Tester | B4: Vũ Hồng
A5: Pass | B5: Fail | C5: Untested | D5: N/A | E5: Number of Test cases | M5: Untested
A6: =COUNTIF(I9:I1007,"Pass") -> 23 | B6: =COUNTIF(I9:I1007,"Fail") -> 0 | C6: =E6-D6-A6-B6 -> 1 | D6: =COUNTIF(H$9:I$1007,"N/A") -> 0 | E6: =COUNTA(A9:A1011) -> 24 | M6: N/A
A8: ID | B8: Group Name | C8: Sub Group Name | D8: Test Case Description | E8: Precondition | F8: Test Case Procedure | G8: Test data | H8: Expected Output | I8: Result | J8: Test date | K8: Note
A9: =$B$2&"-"&ROW()-8 -> Tìm kiếm-1 | B9: Access right | D9: Kiểm tra khách hàng tìm kiếm khi chưa đăng nhập | E9: Chưa đăng nhập | F9: 1. Mở trang chủ 2. Nhập tên sản phẩm muốn tìm kiếm 3. Click button Tìm kiếm | H9: 1. Hệ thống cho phép khách vãng lai tìm kiếm 2. Hiển thị kết quả tìm kiếm | I9: Pass
A10: =$B$2&"-"&ROW()-8 -> Tìm kiếm-2 | D10: Kiểm tra khách hàng tìm kiếm khi đã đăng nhập | E10: Đã đăng nhập | F10: 1. Mở trang chủ 2. Nhập tên sản phẩm muốn tìm kiếm 3. Click button Tìm kiếm | G10: tài khoản: test_1 mật khẩu: 123456789 | H10: 1. Hệ thống hiển thị kết quả tìm kiếm | I10: Pass
A11: =$B$2&"-"&ROW()-8 -> Tìm kiếm-3 | B11: UI | D11: Kiểm tra số lượng các items | F11: 1. View màn hình 2. So sánh với design | H11: 1. Số lượng các item trên màn hình như sau: - text box: Tìm kiếm - button: icon Tìm kiếm | I11: Pass
A12: =$B$2&"-"&ROW()-8 -> Tìm kiếm-4 | D12: Kiểm tra vị trí, font chữ, size chữ, màu sắc | F12: 1. Kiểm tra vị trí, font chữ, size chữ, màu sắc | H12: 1. Hiển thị theo đúng design | I12: Pass
A13: =$B$2&"-"&ROW()-8 -> Tìm kiếm-5 | D13: Kiểm tra trạng thái | F13: 1. Kiểm tra trạng thái các items | H13: 1. Các item đều ở trạng thái enable | I13: Pass
A14: =$B$2&"-"&ROW()-8 -> Tìm kiếm-6 | D14: Kiểm tra giá trị default | F14: 1. Kiểm tra các giá trị default | H14: 1. Các text box đều hiển thị trắng | I14: Pass
A15: =$B$2&"-"&ROW()-8 -> Tìm kiếm-7 | B15: Biz | C15: Tìm kiếm | D15: Bỏ trống thanh tìm kiếm | E15: Khách hàng đang ở ô tìm kiếm | F15: 1. Bỏ trống 2. Click button Tìm kiếm | G15: Tìm kiếm: trống | H15: Hệ thống hiển thị tất cả các sản phẩm đang có | I15: Pass
A16: =$B$2&"-"&ROW()-8 -> Tìm kiếm-8 | D16: Kiểm tra khách hàng nhập từ khóa chứa kí tự đặc biệt | E16: Khách hàng đang ở ô tìm kiếm | F16: 1. Nhập từ khóa chứa kí tự đặc biệt 2. Click buttin Tìm kiếm | G16: Tìm kiếm: @@@ | H16: Hệ thống hiển thị thông báo "Không tìm thấy sản phẩm nào cho từ khóa: @@@" | I16: Pass
A17: =$B$2&"-"&ROW()-8 -> Tìm kiếm-9 | D17: Kiểm tra khách hàng nhập từ khóa là số | E17: Khách hàng đang ở ô tìm kiếm | F17: 1. Nhập từ khóa chứa số 2. Click buttin Tìm kiếm | G17: Tìm kiếm: 123 | H17: Hệ thống hiển thị thông báo "Không tìm thấy sản phẩm nào cho từ khóa: 123" | I17: Pass
A18: =$B$2&"-"&ROW()-8 -> Tìm kiếm-10 | D18: Kiểm tra khách hàng nhập từ khóa là chữ + số | E18: Khách hàng đang ở ô tìm kiếm | F18: 1. Nhập từ khóa chứa chữ và số 2. Click button Tìm kiếm | G18: Tìm kiếm: Áo12 | H18: Hệ thống hiển thị thông báo "Không tìm thấy sản phẩm nào cho từ khóa: Áo12" | I18: Pass
A19: =$B$2&"-"&ROW()-8 -> Tìm kiếm-11 | D19: Kiểm tra khách hàng nhập từ khóa là chữ + kí tự đặc biệt | E19: Khách hàng đang ở ô tìm kiếm | F19: 1. Nhập từ khóa chứa chữ và kí tự đặc biệt 2. Click button Tìm kiếm | G19: Tìm kiếm: Áo@@@ | H19: Hệ thống hiển thị thông báo "Không tìm thấy sản phẩm nào cho từ khóa: Áo@@@" | I19: Pass
A20: =$B$2&"-"&ROW()-8 -> Tìm kiếm-12 | D20: Kiểm tra khách hàng nhập từ khóa là số + kí tự đặc biệt | E20: Khách hàng đang ở ô tìm kiếm | F20: 1. Nhập từ khóa chứa số và kí tự đặc biệt 2. Click button Tìm kiếm | G20: Tìm kiếm: 12@ | H20: Hệ thống hiển thị thông báo "Không tìm thấy sản phẩm nào cho từ khóa: 12@" | I20: Pass
A21: =$B$2&"-"&ROW()-8 -> Tìm kiếm-13 | D21: Kiểm tra khách hàng nhập từ khóa là chữ thường + in hoa | E21: Khách hàng đang ở ô tìm kiếm | F21: 1. Nhập từ khóa chứa chữ thường và chữ in hoa 2. Click button Tìm kiếm | G21: Tìm kiếm: áO | H21: Hệ thống hiển thị sản phẩm có từ khóa phù hợp | I21: Pass
A22: =$B$2&"-"&ROW()-8 -> Tìm kiếm-14 | D22: Kiểm tra khách hàng nhập từ khóa là chữ in hoa | E22: Khách hàng đang ở ô tìm kiếm | F22: 1. Nhập từ khóa chứa chữ in hoa 2. Click button Tìm kiếm | G22: Tìm kiếm: ÁO | H22: Hệ thống hiển thị sản phẩm có từ khóa phù hợp | I22: Pass
A23: =$B$2&"-"&ROW()-8 -> Tìm kiếm-15 | D23: Kiểm tra khách hàng tìm kiếm sản phẩm với tên trùng lặp | E23: Tồn tài 2 sản phẩm cùng tên Khách hàng đang ở ô tìm kiếm | F23: 1. Nhập từ khóa trùng tên 2. Click button Tìm kiếm | G23: Tìm kiếm: Quần khaki nam slimfit | H23: Hệ thống hiển thị tất cả các sản phẩm có tên trùng từ khóa | I23: Pass
A24: =$B$2&"-"&ROW()-8 -> Tìm kiếm-16 | D24: Kiểm tra khách hàng nhập từ khóa có 1 kí tự | E24: Khách hàng đang ở ô tìm kiếm | F24: 1. Nhập từ khóa là 1 kí tự 2. Click button Tìm kiếm | G24: Tìm kiếm: a | H24: Hệ thống hiển thị tất cả các sản phẩm liên quan đến từ khóa | I24: Pass
A25: =$B$2&"-"&ROW()-8 -> Tìm kiếm-17 | D25: Kiểm tra khách hàng tìm kiếm khi ấn enter | E25: Khách hàng đang ở ô tìm kiếm | F25: 1. Nhập từ khóa bất kì 2. Nhấn enter | G25: Tìm kiếm: Áo sơ mi | H25: Hệ thống cho phép tìm kiếm khi ấn enter | I25: Pass
A26: =$B$2&"-"&ROW()-8 -> Tìm kiếm-18 | D26: Kiểm tra khách hàng nhập từ khóa không dấu | E26: Khách hàng đang ở ô tìm kiếm | F26: 1. Nhập từ khóa bất kì không dấu 2. Click button Tìm kiếm | G26: Tìm kiếm: Ao ba lo | H26: Hệ thống hiển thị thông báo "Không tìm thấy sản phẩm nào cho từ khóa: Ao ba lo" | I26: Pass
A27: =$B$2&"-"&ROW()-8 -> Tìm kiếm-19 | D27: Kiểm tra khách hàng tìm kiếm với tên sản phẩm viết sai chính tả | E27: Khách hàng đang ở ô tìm kiếm | F27: 1. Nhập từ khóa bất kì nhưng viết sai chính tả 2. Click button Tìm kiếm | G27: Tìm kiếm: Áo thun lam | H27: Hệ thống hiển thị thông báo "Không tìm thấy sản phẩm nào cho từ khóa: Áo thun lam" | I27: Pass
... A32: =$B$2&"-"&ROW()-8 -> Tìm kiếm-24 | D32: Lỗi DB khi tìm kiếm | E32: Khách hàng đang ở ô tìm kiếm DB đang bị lỗi | F32: 1. Nhập từ khóa tồn tại trong DB 2. Click button Tìm kiếm | G32: Tìm kiếm: Áo sơ mi nam trơn | H32: Hiển thị thông báo "Lỗi hệ thống" | I32: Untested

Sheet Login
A2: Module Code | B2: Đăng nhập | M2: Pass
A3: Test requirement | B3: Hệ thống phải đăng nhập vào trang chủ khi nhập tài khoản đã đăng ký | M3: Fail
A4: Tester | B4: Vũ Hồng
A5: Pass | B5: Fail | C5: Untested | D5: N/A | E5: Number of Test cases | M5: Untesed
A6: =COUNTIF(I9:I1001,"Pass") -> 15 | B6: =COUNTIF(I9:I1001,"Fail") -> 1 | C6: =E6-D6-A6-B6 -> 1 | D6: =COUNTIF(H$9:I$1001,"N/A") -> 0 | E6: =COUNTA(A9:A1005) -> 17 | M6: N/A
A8: ID | B8: Group Name | C8: Sub Group Name | D8: Test Case Description | E8: Precondition | F8: Test Case Procedure | G8: Test data | H8: Expected Output | I8: Result | J8: Test date | K8: Note
A9: =$B$2&"-"&ROW()-8 -> Đăng nhập-1 | B9: Access right | D9: Kiểm tra user đăng nhập với tư cách là khách hàng | E9: 1. Đã có tài khoản 2. Đang ở trang đăng nhập | F9: 1. Vào trang chủ 2. Click Tài khoản trên thanh menu 3. Chọn Đăng nhập | G9: tài khoản: test_1 mật khẩu: 123456789 | H9: 1. Hệ thống sẽ đi đến màn hình trang chủ | I9: Pass
A10: =$B$2&"-"&ROW()-8 -> Đăng nhập-2 | D10: Kiểm tra quyền truy cập với tư cách là admin | E10: 1. Có tài khoản admin 2. Đang ở trang đăng nhập | F10: 1. Vào trang chủ 2. Click Tài khoản trên thanh menu 3. Chọn Đăng nhập | G10: tài khoản: admin mật khẩu: admin | H10: Hệ thống sẽ hiển thị thống báo "Tài khoản hoặc mật khẩu không đúng" | I10: Pass
A11: =$B$2&"-"&ROW()-8 -> Đăng nhập-3 | B11: UI | D11: Kiểm tra số lượng các items | F11: 1. View màn hình 2. So sánh với design | H11: 1. Số lượng các item trên màn hình như sau: - text box: Tài khoản, Mật khẩu - button: Đăng nhập | I11: Pass
A12: =$B$2&"-"&ROW()-8 -> Đăng nhập-4 | D12: Kiểm tra vị trí, font chữ, size chữ, màu sắc | F12: 1. Kiểm tra vị trí, font chữ, size chữ, màu sắc | H12: Hiển thị đúng theo design | I12: Pass
A13: =$B$2&"-"&ROW()-8 -> Đăng nhập-5 | D13: Kiểm tra trạng thái | F13: 1. Kiểm tra trạng thái các items | H13: Các item đều ở trạng thái enable | I13: Pass
A14: =$B$2&"-"&ROW()-8 -> Đăng nhập-6 | D14: Kiểm tra giá trị default | F14: 1. Kiểm tra các giá trị default | H14: Các text box đều hiển thị trắng | I14: Pass
A15: =$B$2&"-"&ROW()-8 -> Đăng nhập-7 | B15: Validation | C15: Tài khoản | D15: Bỏ trống tài khoản | E15: Khách hàng đang ở form đăng nhập | F15: 1. Bỏ trống tài khoản 2. Nhập mật khẩu hợp lệ 3. Click button Đăng nhập | G15: Tài khoản: trống | H15: Hệ thống hiển thị thông báo "Vui lòng nhập thông tin" | I15: Pass | K15: Please fill out this field Tùy vào Chorme cài
A16: =$B$2&"-"&ROW()-8 -> Đăng nhập-8 | D16: Kiểm tra khách hàng nhập sai tài khoản | E16: Tài khoản đã được đăng ký | F16: 1. Nhập tài khoản sai chính tả 2. Nhập mật khẩu hợp lệ 3. Click button Đăng nhập | G16: Tài khoản: tets_1 | H16: 1. Hệ thống hiển thị thông báo "Tài khoản hoặc mật khẩu không đúng!" | I16: Pass
A17: =$B$2&"-"&ROW()-8 -> Đăng nhập-9 | D17: Kiểm tra khách hàng nhập tài khoản không tồn tại | E17: Tài khoản chưa được đăng ký | F17: 1. Nhập tài khoản chưa đăng ký 2. Nhập mật khẩu hợp lệ 3. Click button Đăng nhập | G17: Tài khoản: haha | H17: 1. Hệ thống hiển thị thông báo "Tài khoản hoặc mật khẩu không đúng!" | I17: Pass
A18: =$B$2&"-"&ROW()-8 -> Đăng nhập-10 | D18: Kiểm tra khách hàng nhập tài khoản đúng nhưng phân biệt hoa thường | E18: Tài khoản đã được đăng ký | F18: 1. Nhập tài khoản đúng nhưng phân biệt hoa thường 2. Nhập mật khẩu hợp lệ 3. Click button Đăng nhập | G18: Tài khoản: Test_1 | H18: 1. Hệ thống hiển thị thông báo "Tài khoản hoặc mật khẩu không đúng!" | I18: Fail | K18: Hệ thống cho phép nhập tên không phân biệt hoa thường
A19: =$B$2&"-"&ROW()-8 -> Đăng nhập-11 | D19: Kiểm tra khách hàng nhập tài khoản hợp lệ | E19: Tài khoản đã được đăng ký | F19: 1. Nhập tài khoản tồn tại trong DB 2. Nhập mật khẩu hợp lệ 3. Click button Đăng nhập | G19: Tài khoản: test_1 | H19: 1. Hệ thống không hiển thị thông báo | I19: Pass
A20: =$B$2&"-"&ROW()-8 -> Đăng nhập-12 | C20: Mật khẩu | D20: Bỏ trống mật khẩu | E20: Khách hàng đang ở form đăng nhập | F20: 1. Bỏ trống mật khẩu 2. Nhập mật tài khoản hợp lệ 3. Click button Đăng nhập | G20: Mật khẩu: | H20: Hệ thống hiển thị thông báo "Vui lòng nhập thông tin" | I20: Pass
A21: =$B$2&"-"&ROW()-8 -> Đăng nhập-13 | D21: Kiểm tra khách hàng nhập sai mật khẩu | E21: Khách hàng đang ở form đăng nhập | F21: 1. Nhập mật khẩu không tồn tại trong DB 2. Nhập tài khoản hợp lệ 3. Click button Đăng nhập | G21: Mật khẩu: 123 | H21: 1. Hệ thống hiển thị thông báo "Tài khoản hoặc mật khẩu không đúng!" | I21: Pass
A22: =$B$2&"-"&ROW()-8 -> Đăng nhập-14 | D22: Kiểm tra khách hàng nhập mật khẩu hợp lệ | E22: Khách hàng đang ở form đăng nhập | F22: 1. Nhập mật khẩu tồn tại trong DB 2. Nhập tài khoản hợp lệ 3. Click button Đăng nhập | G22: Mật khẩu: 123456789 | H22: Hệ thống không hiển thị thông báo | I22: Pass
A23: =$B$2&"-"&ROW()-8 -> Đăng nhập-15 | B23: Biz | C23: Button Đăng nhập | D23: Kiểm tra khách hàng đăng nhập thành công vào website | E23: 1. Khách hàng đang ở form đăng nhập 2. Tài khoản đã được đăng ký | F23: 1. Nhập tài khoản hợp lệ 2. Nhập mật khẩu hợp lệ 3. Click button Đăng nhập | G23: Tài khoản: test_1 Mật khẩu: 123456789 | H23: Hệ thống chuyển đến màn hình trang chủ | I23: Pass
A24: =$B$2&"-"&ROW()-8 -> Đăng nhập-16 | D24: Kiểm tra khách hàng đăng nhập không thành công do tài khoản bị vô hiệu hóa | E24: 1. Khách hàng đang ở form đăng nhập 2. Tài khoản đã được đăng ký | F24: 1. Nhập tài khoản hợp lệ 2. Nhập mật khẩu hợp lệ 3. Click button Đăng nhập | G24: Tài khoản: a Mật khẩu: 123456789 | H24: 1. Hệ thống hiển thị thông báo "Tài khoản của bạn đã bị vô hiệu hóa !" | I24: Pass
A25: =$B$2&"-"&ROW()-8 -> Đăng nhập-17 | D25: Lỗi DB khi đăng nhập | E25: 1. Khách hàng đang ở form đăng nhập 2. Tài khoản đã được đăng ký 3. Lỗi DB | F25: 1. Nhập tài khoản hợp lệ 2. Nhập mật khẩu hợp lệ 3. Click button Đăng nhập | G25: Tài khoản: test_1 Mật khẩu: 123456789 | H25: Hệ thống hiển thị thông báo "Lỗi hệ thống" | I25: Untesed | K25: Cần giả lập DB

Sheet Cover
B2: Logo | C2: TEST CASE
B4: Project Name | C4: DATN_TrueMart_Auto | F4: Creator
B5: Project Code | C5: DATN | F5: Reviewer/Approver
B6: Document Code | C6: DATN_1 | F6: Issue Date
F7: Version | G7: 1.1
B10: Record of change
B11: Effective Date | C11: Version | D11: Change Item | E11: *A,D,M | F11: Change description | G11: Reference
B12: 44507 | C12: 1.0 | E12: A | F12: Tạo mới file | G12: <List of documents which are referred in this version.>
B13: 30/7/2021 | C13: 1.1 | E13: M | F13: Update ...

Sheet Test case List
D1: TEST CASE LIST
B3: Project Name | D3: =Cover!C4 -> DATN_TrueMart_Auto
B4: Project Code | D4: DATN
B5: Test Environment Setup Description | D5: 1. Server: localhost 2. Databasse: SQL Server 2019 3. Web Browser: Chrome Version 147.0.7727.102 (Official Build) (64-bit) 4. URL: https://localhost:44392 5. OS: Windows 11
B8: No | C8: Function Name | D8: Sheet Name | E8: Description | F8: Pre-Condition
B9: 1 | C9: Login | D9: Login | E9: =Login!B3 -> Hệ thống phải đăng nhập vào trang chủ khi nhập tài khoản đã đăng ký | F9: Khách hàng đã đăng ký tài khoản
B10: 2 | C10: Search | D10: Search | E10: =Search!B3 -> Người dùng nhập từ khóa vào thanh tìm kiếm trên menu - Nếu đúng: hiển thị sản phẩm - Nếu sai: hiển thị thông báo | F10: Khách hàng đang ở ô tìm kiếm
B11: 3 | C11: Category | D11: Category | E11: =Category!B3 -> Hệ thống hiển thị tất cả các danh mục đang có khi click vào Sản phẩm trên thanh menu | F11: Đang ở trang chủ
B12: 4 | C12: Product_detail | D12: Product_detail | E12: =Product_detail!B3 -> Hệ thống hiển thị thông tin chi tiết sản phẩm khi click vào một sản phẩm bất kỳ. Có thể: - Xem đánh giá - Thêm sản phẩm vào giỏ | F12: Đang ở trang chủ
B13: 5 | C13: Register | D13: Register | E13: =Register!B3 -> Hệ thống tạo tài khoản thành công khi nhập các thông tin hợp lệ | F13: Đang ở màn hình đăng ký
B14: 6 | C14: Order | D14: Order | E14: =Order!B3 -> Hệ thống đặt hàng thành công với các sản phẩm có trong giỏ hàng | F14: Đang ở giỏ hàng
B15: 7 | C15: Cart | D15: Cart | E15: =Cart!B3 -> Hệ thống cho phép khách hàng xem sản phẩm trong giỏ, sửa số lượng, xóa sản phẩm khỏi giỏ hàng | F15: Đang ở giỏ hàng
B16: 8 | C16: Invoice | D16: Invoice | E16: =Invoice!B3 -> Hệ thống cho phép người quản trị xem hóa đơn, hủy đơn hàng và chỉnh sửa trạng thái đơn hàng | F16: Đang ở trang hóa đơn

Sheet Test Report
B1: TEST REPORT
B3: Project Name | C3: DATN_TrueMart_Auto | E3: Creator | H3: Vũ Thị Hồng
B4: Project Code | C4: DATN | E4: Reviewer/Approver | H4: ThS. Phạm Thị Kim Phượng
B5: Document Code | C5: DATN_TestReport_v1.0 | E5: Issue Date | H5: 46136
B6: Notes | C6: Gồm 8 module: Đăng ký, Đăng nhập, Xem danh mục sản phẩm, Tìm kiếm sản phẩm, Xem chi tiết sản phẩm, Quản lí giỏ hàng, Đặt hàng, Quản lí hóa đơn
B10: No | C10: Module code | D10: Pass | E10: Fail | F10: Untested | G10: N/A | H10: Number of test cases
B11: 1 | C11: =Login!B2 -> Đăng nhập | D11: =Login!A6 -> 15 | E11: =Login!B6 -> 1 | F11: =Login!C6 -> 1 | G11: =Login!D6 -> 0 | H11: =Login!E6 -> 17
B12: 2 | C12: Đăng ký tài khoản | D12: =Register!A6 -> 39 | E12: =Register!B6 -> 17 | F12: =Register!C6 -> 1 | G12: 0 | H12: =Register!E6 -> 57
B13: 3 | C13: Tìm kiếm sản phẩm | D13: =Search!A6 -> 23 | E13: =Search!B6 -> 0 | F13: =Search!C6 -> 1 | G13: =Search!D6 -> 0 | H13: =Search!E6 -> 24
B14: 4 | C14: Xem danh mục sản phẩm | D14: =Category!A6 -> 7 | E14: =Category!B6 -> 0 | F14: =Category!C6 -> 2 | G14: 0 | H14: =Category!E6 -> 9
B15: 5 | C15: Xem chi tiết sản phẩm | D15: =Product_detail!A6 -> 10 | E15: =Product_detail!B6 -> 5 | F15: =Product_detail!C6 -> 1 | G15: 0 | H15: =Product_detail!E6 -> 16
B16: 6 | C16: Đặt hàng | D16: =Order!A6 -> 11 | E16: =Order!B6 -> 0 | F16: =Order!C6 -> 1 | G16: 0 | H16: =Order!E6 -> 12
B17: 7 | C17: Quản lí giỏ hàng | D17: =Cart!A6 -> 21 | E17: =Cart!B6 -> 4 | F17: =Cart!C6 -> 1 | G17: 0 | H17: =Cart!E6 -> 26
B18: 8 | C18: Quản lí hóa đơn | D18: =Invoice!A6 -> 12 | E18: =Invoice!B6 -> 1 | F18: =Invoice!C6 -> 1 | G18: 1 | H18: =Invoice!E6 -> 15
C19: Sub total | D19: =SUM(D11:D18) -> 138 | E19: =SUM(E11:E18) -> 28 | F19: =SUM(F11:F18) -> 9 | G19: =SUM(G11:G18) -> 1 | H19: =SUM(H9:H18) -> 176
C21: Test coverage | E21: =(D19+E19)*100/(H19-G19) -> 94.857143 | F21: %
C22: Test successful coverage | E22: =D19*100/(H19-G19) -> 78.857143 | F22: %
